Workbook

Sheet 经济技术指标
A1: 主要经济技术指标
A2: 项目名称：{{PROJECT_NAME}}
A3: 序号 | B3: 指标名称 | C3: 单位 | D3: 数值 | E3: 备注
A4: 1 | B4: 用地面积 | C4: ㎡
A5: 2 | B5: 总建筑面积 | C5: ㎡ | D5: =D6+D9
A6: 3 | B6: 地下总建筑面积 | C6: ㎡ | D6: =SUM(D7:D8)
A7: 3.1 | B7: A区地下室 | C7: ㎡
A8: 3.1 | B8: B区地下室 | C8: ㎡
A9: 4 | B9: 地上总建筑面积 | C9: ㎡ | D9: =SUM(D10:D13)
A10: 4.1 | B10: 1#楼 | C10: ㎡
A11: 4.2 | B11: 2#楼 | C11: ㎡
A12: 4.3 | B12: 3#楼 | C12: ㎡
A13: 4.4 | B13: 构筑物 | C13: ㎡
A14: 5 | B14: 占地面积 | C14: ㎡ | D14: =SUM(D15:D16)
A15: 5.1 | B15: A区地块 | C15: ㎡
A16: 5.2 | B16: B区地块 | C16: ㎡
A17: 6 | B17: 室外面积 | C17: ㎡ | D17: =D4-D14
A18: 7 | B18: 机动车位停车 | C18: 辆 | D18: =SUM(D19:D20)
A19: 7.1 | B19: 地面机动车停车 | C19: 辆
A20: 7.2 | B20: 地下机动车停车 | C20: 辆

Sheet 估概算总表
A1: 工程建设投资概算总表
A2: 项目名称：{{PROJECT_NAME}}
A3: 序号 | B3: 工程或费用名称 | C3: 费用 （万元） | D3: 占总投资比例 （%） | E3: 技术经济指标
E4: 单位 （x） | F4: 数量 | G4: 单方指标 （元/x） | H4: 计算基数 | I4: 指标 说明
A5: 一 | B5: 工程费用 | C5: =C6+C9+C12+C15+C18+C21+C24+C34 | D5: =C5/C50 | E5: ㎡ | F5: =经济技术指标!$D$5 | G5: =C5/F5*10000 | H5: 总建筑面积 | I5: 项目工程 指标
A6: 1 | B6: A区地下室工程 | C6: =C7+C8 | D6: =C6/C50 | E6: ㎡ | F6: =经济技术指标!$D$7 | G6: =C6/F6*10000 | H6: 单体建筑面积 | I6: 单项工程指标
A7: 1.1 | B7: 建筑工程费 | C7: ='1.建筑工程费'!C6 | E7: ㎡ | F7: =经济技术指标!$D$7 | G7: =C7/F7*10000 | H7: 单体建筑面积 | I7: 单位工程指标
A8: 1.2 | B8: 安装工程费 | C8: ='2.安装工程费'!C6 | E8: ㎡ | F8: =经济技术指标!$D$7 | G8: =C8/F8*10000 | H8: 单体建筑面积 | I8: 单位工程指标
A9: 2 | B9: B区地下室工程 | C9: =C10+C11 | D9: =C9/C50 | E9: ㎡ | F9: =经济技术指标!$D$8 | G9: =C9/F9*10000 | H9: 单体建筑面积 | I9: 单项工程指标
A10: 2.1 | B10: 建筑工程费 | C10: ='1.建筑工程费'!C15 | E10: ㎡ | F10: =经济技术指标!$D$8 | G10: =C10/F10*10000 | H10: 单体建筑面积 | I10: 单位工程指标
A11: 2.2 | B11: 安装工程费 | C11: ='2.安装工程费'!C14 | E11: ㎡ | F11: =经济技术指标!$D$8 | G11: =C11/F11*10000 | H11: 单体建筑面积 | I11: 单位工程指标
A12: 3 | B12: 1#楼工程 | C12: =C13+C14 | D12: =C12/C50 | E12: ㎡ | F12: =经济技术指标!$D$10 | G12: =C12/F12*10000 | H12: 单体建筑面积 | I12: 单项工程指标
A13: 3.1 | B13: 建筑工程费 | C13: ='1.建筑工程费'!C24 | E13: ㎡ | F13: =经济技术指标!$D$10 | G13: =C13/F13*10000 | H13: 单体建筑面积 | I13: 单位工程指标
A14: 3.2 | B14: 安装工程费 | C14: ='2.安装工程费'!C22 | E14: ㎡ | F14: =经济技术指标!$D$10 | G14: =C14/F14*10000 | H14: 单体建筑面积 | I14: 单位工程指标
A15: 4 | B15: 2#楼工程 | C15: =C16+C17 | D15: =C15/C50 | E15: ㎡ | F15: =经济技术指标!$D$11 | G15: =C15/F15*10000 | H15: 单体建筑面积 | I15: 单项工程指标
A16: 4.1 | B16: 建筑工程费 | C16: ='1.建筑工程费'!C30 | E16: ㎡ | F16: =经济技术指标!$D$11 | G16: =C16/F16*10000 | H16: 单体建筑面积 | I16: 单位工程指标
A17: 4.2 | B17: 安装工程费 | C17: ='2.安装工程费'!C31 | E17: ㎡ | F17: =经济技术指标!$D$11 | G17: =C17/F17*10000 | H17: 单体建筑面积 | I17: 单位工程指标
A18: 5 | B18: 3#楼工程 | C18: =C19+C20 | D18: =C18/C50 | E18: ㎡ | F18: =经济技术指标!$D$12 | G18: =C18/F18*10000 | H18: 单体建筑面积 | I18: 单项工程指标
A19: 5.1 | B19: 建筑工程费 | C19: ='1.建筑工程费'!C36 | E19: ㎡ | F19: =经济技术指标!$D$12 | G19: =C19/F19*10000 | H19: 单体建筑面积 | I19: 单位工程指标
A20: 5.2 | B20: 安装工程费 | C20: ='2.安装工程费'!C40 | E20: ㎡ | F20: =经济技术指标!$D$12 | G20: =C20/F20*10000 | H20: 单体建筑面积 | I20: 单位工程指标
A21: 6 | B21: 构筑物（***）工程 | C21: =C22+C23 | D21: =C21/C50 | E21: ㎡ | F21: =经济技术指标!$D$13 | G21: =C21/F21*10000 | H21: 单体建筑面积 | I21: 单项工程指标
A22: 6.1 | B22: 建筑工程费 | C22: ='1.建筑工程费'!C42 | E22: ㎡ | F22: =经济技术指标!$D$13 | G22: =C22/F22*10000 | H22: 单体建筑面积 | I22: 单位工程指标
A23: 6.2 | B23: 安装工程费 | C23: ='2.安装工程费'!C49 | E23: ㎡ | F23: =经济技术指标!$D$13 | G23: =C23/F23*10000 | H23: 单体建筑面积 | I23: 单位工程指标
A24: 7 | B24: 专项工程费 | C24: =SUM(C25:C33) | D24: =C24/C50 | E24: ㎡ | F24: =经济技术指标!$D$5 | G24: =C24/F24*10000 | H24: 总建筑面积 | I24: 单项工程指标
A25: 7.1 | B25: ='3.专项工程费'!B6 | C25: ='3.专项工程费'!C6 | E25: ㎡ | F25: =经济技术指标!$D$5 | G25: =C25/F25*10000 | H25: 总建筑面积 | I25: 专项工程指标
A26: 7.2 | B26: ='3.专项工程费'!B19 | C26: ='3.专项工程费'!C19 | E26: ㎡ | F26: ='3.专项工程费'!E19 | G26: =C26/F26*10000 | H26: 区域建筑面积 | I26: 专项工程指标
A27: 7.3 | B27: ='3.专项工程费'!B29 | C27: ='3.专项工程费'!C29 | E27: ㎡ | F27: ='3.专项工程费'!E29 | G27: =C27/F27*10000 | H27: 区域建筑面积 | I27: 专项工程指标
A28: 7.4 | B28: ='3.专项工程费'!B35 | C28: ='3.专项工程费'!C35 | E28: ㎡ | F28: ='3.专项工程费'!E35 | G28: =C28/F28*10000 | H28: 区域建筑面积 | I28: 专项工程指标
A29: 7.5 | B29: ='3.专项工程费'!B42 | C29: ='3.专项工程费'!C42 | E29: ㎡ | F29: ='3.专项工程费'!E42 | G29: =C29/F29*10000 | H29: 区域建筑面积 | I29: 专项工程指标
A30: 7.6 | B30: ='3.专项工程费'!B46 | C30: ='3.专项工程费'!C46 | E30: ㎡ | F30: ='3.专项工程费'!E35 | G30: =C30/F30*10000 | H30: 区域建筑面积 | I30: 专项工程指标
A31: 7.7 | B31: ='3.专项工程费'!B47 | C31: ='3.专项工程费'!C47 | E31: ㎡ | F31: ='3.专项工程费'!E47 | G31: =C31/F31*10000 | H31: 区域建筑面积 | I31: 专项工程指标
A32: 7.8 | B32: ='3.专项工程费'!B48 | C32: ='3.专项工程费'!C48 | E32: ㎡ | F32: ='3.专项工程费'!E48 | G32: =C32/F32*10000 | H32: 区域建筑面积 | I32: 专项工程指标
A33: 7.9 | B33: ='3.专项工程费'!B49 | C33: ='3.专项工程费'!C49 | E33: ㎡ | F33: ='3.专项工程费'!E49 | G33: =C33/F33*10000 | H33: 区域建筑面积 | I33: 专项工程指标
A34: 8 | B34: 室外及配套工程费 | C34: =SUM(C35:C43) | D34: =C34/C50 | E34: ㎡ | F34: =经济技术指标!$D$5 | G34: =C34/F34*10000 | H34: 总建筑面积 | I34: 单项工程指标
A35: 8.1 | B35: ='4.室外及配套工程费'!B6 | C35: ='4.室外及配套工程费'!C6 | E35: ㎡ | F35: =经济技术指标!$D$17 | G35: =C35/F35*10000 | H35: 室外面积 | I35: 单位工程指标
A36: 8.2 | B36: 室外市政工程 | C36: ='4.室外及配套工程费'!C10 | E36: ㎡ | F36: =经济技术指标!$D$17 | G36: =C36/F36*10000 | H36: 室外面积 | I36: 单位工程指标
A37: 8.3 | B37: 室外附属工程 | C37: ='4.室外及配套工程费'!C15 | E37: ㎡ | F37: =经济技术指标!$D$17 | G37: =C37/F37*10000 | H37: 室外面积 | I37: 单位工程指标
A38: 8.4 | B38: 室外安装工程 | C38: ='4.室外及配套工程费'!C21 | E38: ㎡ | F38: =经济技术指标!$D$17 | G38: =C38/F38*10000 | H38: 室外面积 | I38: 单位工程指标
A39: 8.5 | B39: 变配电配套工程 | C39: ='4.室外及配套工程费'!C27 | E39: ㎡ | F39: =经济技术指标!$D$5 | G39: =C39/F39*10000 | H39: 总建筑面积 | I39: 单位工程指标
A40: 8.6 | B40: 供水配套工程 | C40: ='4.室外及配套工程费'!C28 | E40: ㎡ | F40: =经济技术指标!$D$5 | G40: =C40/F40*10000 | H40: 总建筑面积 | I40: 单位工程指标
...

Sheet 1.建筑工程费
A1: 建筑工程费专业分析表
A2: 项目名称：{{PROJECT_NAME}}
A3: 序号 | B3: 工程或费用名称 | C3: 费用 （万元） | D3: 技术经济指标
D4: 单位 （x） | E4: 数量 | F4: 单方指标 （元/x） | G4: 计算基数 | H4: 指标 说明
A5: 1 | B5: 建筑工程费 | C5: =C6+C15+C24+C30+C36+C42 | D5: ㎡ | E5: =经济技术指标!$D$5 | F5: =C5/E5*10000 | G5: 总建筑面积
A6: 1.1 | B6: A区地下室工程 | C6: =SUM(C7:C14) | D6: ㎡ | E6: =经济技术指标!$D$7 | F6: =C6/E6*10000 | G6: 单体建筑面积 | H6: 单位工程指标
A7: 1.1.1 | B7: 土石方工程 | D7: ㎡ | E7: =经济技术指标!$D$7 | F7: =C7/E7*10000 | G7: 单体建筑面积 | H7: 专业工程指标
A8: 1.1.2 | B8: 地基处理工程 | D8: ㎡ | E8: =经济技术指标!$D$7 | F8: =C8/E8*10000 | G8: 单体建筑面积 | H8: 专业工程指标
A9: 1.1.3 | B9: 基坑围护工程 | D9: ㎡ | E9: =经济技术指标!$D$7 | F9: =C9/E9*10000 | G9: 单体建筑面积 | H9: 专业工程指标
A10: 1.1.4 | B10: 桩基工程 | D10: ㎡ | E10: =经济技术指标!$D$7 | F10: =C10/E10*10000 | G10: 单体建筑面积 | H10: 专业工程指标
A11: 1.1.5 | B11: 建筑工程 | D11: ㎡ | E11: =经济技术指标!$D$7 | F11: =C11/E11*10000 | G11: 单体建筑面积 | H11: 专业工程指标
A12: 1.1.6 | B12: 钢结构工程 | D12: ㎡ | E12: =经济技术指标!$D$7 | F12: =C12/E12*10000 | G12: 单体建筑面积 | H12: 专业工程指标
A13: 1.1.7 | B13: 精装修工程 | D13: ㎡ | E13: =经济技术指标!$D$7 | F13: =C13/E13*10000 | G13: 单体建筑面积 | H13: 专业工程指标
B14: ……
A15: 1.2 | B15: B区地下室工程 | C15: =SUM(C16:C23) | D15: ㎡ | E15: =经济技术指标!$D$8 | F15: =C15/E15*10000 | G15: 单体建筑面积 | H15: 单位工程指标
A16: 1.2.1 | B16: 土石方工程 | D16: m³ | E16: =经济技术指标!$D$8 | F16: =C16/E16*10000 | G16: 单体建筑面积 | H16: 专业工程指标
A17: 1.2.2 | B17: 地基处理工程 | D17: ㎡ | E17: =经济技术指标!$D$8 | F17: =C17/E17*10000 | G17: 单体建筑面积 | H17: 专业工程指标
A18: 1.2.2 | B18: 基坑围护工程 | D18: m | E18: =经济技术指标!$D$8 | F18: =C18/E18*10000 | G18: 单体建筑面积 | H18: 专业工程指标
A19: 1.2.3 | B19: 桩基工程 | D19: ㎡ | E19: =经济技术指标!$D$8 | F19: =C19/E19*10000 | G19: 单体建筑面积 | H19: 专业工程指标
A20: 1.2.4 | B20: 建筑工程 | D20: ㎡ | E20: =经济技术指标!$D$8 | F20: =C20/E20*10000 | G20: 单体建筑面积 | H20: 专业工程指标
A21: 1.2.5 | B21: 钢结构工程 | D21: ㎡ | E21: =经济技术指标!$D$8 | F21: =C21/E21*10000 | G21: 单体建筑面积 | H21: 专业工程指标
A22: 1.2.6 | B22: 精装修工程 | D22: ㎡ | E22: =经济技术指标!$D$8 | F22: =C22/E22*10000 | G22: 单体建筑面积 | H22: 专业工程指标
B23: ……
A24: 1.3 | B24: 1#楼工程 | C24: =SUM(C25:C29) | D24: ㎡ | E24: =经济技术指标!$D$10 | F24: =C24/E24*10000 | G24: 单体建筑面积 | H24: 单位工程指标
A25: 1.3.1 | B25: 建筑工程 | D25: ㎡ | E25: =经济技术指标!$D$10 | F25: =C25/E25*10000 | G25: 单体建筑面积 | H25: 专业工程指标
A26: 1.3.2 | B26: 钢结构工程 | D26: ㎡ | E26: =经济技术指标!$D$10 | F26: =C26/E26*10000 | G26: 单体建筑面积 | H26: 专业工程指标
A27: 1.3.3 | B27: 幕墙工程 | D27: ㎡ | E27: =经济技术指标!$D$10 | F27: =C27/E27*10000 | G27: 单体建筑面积 | H27: 专业工程指标
A28: 1.3.4 | B28: 精装修工程 | D28: ㎡ | E28: =经济技术指标!$D$10 | F28: =C28/E28*10000 | G28: 单体建筑面积 | H28: 专业工程指标
B29: ……
A30: 1.4 | B30: 2#楼工程 | C30: =SUM(C31:C35) | D30: ㎡ | E30: =经济技术指标!$D$11 | F30: =C30/E30*10000 | G30: 单体建筑面积 | H30: 单位工程指标
A31: 1.4.1 | B31: 建筑工程 | D31: ㎡ | E31: =经济技术指标!$D$11 | F31: =C31/E31*10000 | G31: 单体建筑面积 | H31: 专业工程指标
A32: 1.4.2 | B32: 钢结构工程 | D32: ㎡ | E32: =经济技术指标!$D$11 | F32: =C32/E32*10000 | G32: 单体建筑面积 | H32: 专业工程指标
A33: 1.4.3 | B33: 幕墙工程 | D33: ㎡ | E33: =经济技术指标!$D$11 | F33: =C33/E33*10000 | G33: 单体建筑面积 | H33: 专业工程指标
A34: 1.4.4 | B34: 精装修工程 | D34: ㎡ | E34: =经济技术指标!$D$11 | F34: =C34/E34*10000 | G34: 单体建筑面积 | H34: 专业工程指标
B35: ……
A36: 1.5 | B36: 3#楼工程 | C36: =SUM(C37:C41) | D36: ㎡ | E36: =经济技术指标!$D$12 | F36: =C36/E36*10000 | G36: 单体建筑面积 | H36: 单位工程指标
A37: 1.5.1 | B37: 建筑工程 | D37: ㎡ | E37: =经济技术指标!$D$12 | F37: =C37/E37*10000 | G37: 单体建筑面积 | H37: 专业工程指标
A38: 1.5.2 | B38: 钢结构工程 | D38: ㎡ | E38: =经济技术指标!$D$12 | F38: =C38/E38*10000 | G38: 单体建筑面积 | H38: 专业工程指标
A39: 1.5.3 | B39: 幕墙工程 | D39: ㎡ | E39: =经济技术指标!$D$12 | F39: =C39/E39*10000 | G39: 单体建筑面积 | H39: 专业工程指标
A40: 1.5.4 | B40: 精装修工程 | D40: ㎡ | E40: =经济技术指标!$D$12 | F40: =C40/E40*10000 | G40: 单体建筑面积 | H40: 专业工程指标
...

Sheet 2.安装工程费
A1: 安装工程费专业分析表
A2: 项目名称：{{PROJECT_NAME}}
A3: 序号 | B3: 工程或费用名称 | C3: 费用 （万元） | D3: 技术经济指标
D4: 单位 （x） | E4: 数量 | F4: 单方指标 （元/x） | G4: 计算基数 | H4: 指标 说明
A5: 2 | B5: 安装工程费 | C5: =C6+C14+C22+C31+C40+C49 | D5: ㎡ | E5: =经济技术指标!$D$5 | F5: =C5/E5*10000 | G5: 总建筑面积
A6: 2.1 | B6: A区地下室工程 | C6: =SUM(C7:C12) | D6: ㎡ | E6: =经济技术指标!$D$7 | F6: =C6/E6*10000 | G6: 单体建筑面积 | H6: 单位工程指标
A7: 2.1.1 | B7: 电气设备安装工程 | D7: ㎡ | E7: =经济技术指标!$D$7 | F7: =C7/E7*10000 | G7: 单体建筑面积 | H7: 专业工程指标
A8: 2.1.2 | B8: 建筑智能化工程 | D8: ㎡ | E8: =经济技术指标!$D$7 | F8: =C8/E8*10000 | G8: 单体建筑面积 | H8: 专业工程指标
A9: 2.1.3 | B9: 通风空调工程 | D9: ㎡ | E9: =经济技术指标!$D$7 | F9: =C9/E9*10000 | G9: 单体建筑面积 | H9: 专业工程指标
A10: 2.1.4 | B10: 消防工程 | D10: ㎡ | E10: =经济技术指标!$D$7 | F10: =C10/E10*10000 | G10: 单体建筑面积 | H10: 专业工程指标
A11: 2.1.5 | B11: 给排水采暖工程 | D11: ㎡ | E11: =经济技术指标!$D$7 | F11: =C11/E11*10000 | G11: 单体建筑面积 | H11: 专业工程指标
A12: 2.1.6 | B12: 电梯工程 | D12: ㎡ | E12: =经济技术指标!$D$7 | F12: =C12/E12*10000 | G12: 单体建筑面积 | H12: 专业工程指标
B13: ……
A14: 2.2 | B14: B区地下室工程 | C14: =SUM(C15:C20) | D14: ㎡ | E14: =经济技术指标!$D$8 | F14: =C14/E14*10000 | G14: 单体建筑面积 | H14: 单位工程指标
A15: 2.2.1 | B15: 电气设备安装工程 | D15: ㎡ | E15: =经济技术指标!$D$8 | F15: =C15/E15*10000 | G15: 单体建筑面积 | H15: 专业工程指标
A16: 2.2.2 | B16: 建筑智能化工程 | D16: ㎡ | E16: =经济技术指标!$D$8 | F16: =C16/E16*10000 | G16: 单体建筑面积 | H16: 专业工程指标
A17: 2.2.3 | B17: 通风空调工程 | D17: ㎡ | E17: =经济技术指标!$D$8 | F17: =C17/E17*10000 | G17: 单体建筑面积 | H17: 专业工程指标
A18: 2.2.4 | B18: 消防工程 | D18: ㎡ | E18: =经济技术指标!$D$8 | F18: =C18/E18*10000 | G18: 单体建筑面积 | H18: 专业工程指标
A19: 2.2.5 | B19: 给排水采暖工程 | D19: ㎡ | E19: =经济技术指标!$D$8 | F19: =C19/E19*10000 | G19: 单体建筑面积 | H19: 专业工程指标
A20: 2.2.6 | B20: 电梯工程 | D20: ㎡ | E20: =经济技术指标!$D$8 | F20: =C20/E20*10000 | G20: 单体建筑面积 | H20: 专业工程指标
B21: ……
A22: 2.3 | B22: 1#楼工程 | C22: =SUM(C23:C29) | D22: ㎡ | E22: =经济技术指标!$D$10 | F22: =C22/E22*10000 | G22: 单体建筑面积 | H22: 单位工程指标
A23: 2.3.1 | B23: 电气设备安装工程 | D23: ㎡ | E23: =经济技术指标!$D$10 | F23: =C23/E23*10000 | G23: 单体建筑面积 | H23: 专业工程指标
A24: 2.3.2 | B24: 建筑智能化工程 | D24: ㎡ | E24: =经济技术指标!$D$10 | F24: =C24/E24*10000 | G24: 单体建筑面积 | H24: 专业工程指标
A25: 2.3.3 | B25: 通风空调工程 | D25: ㎡ | E25: =经济技术指标!$D$10 | F25: =C25/E25*10000 | G25: 单体建筑面积 | H25: 专业工程指标
A26: 2.3.4 | B26: 消防工程 | D26: ㎡ | E26: =经济技术指标!$D$10 | F26: =C26/E26*10000 | G26: 单体建筑面积 | H26: 专业工程指标
A27: 2.3.5 | B27: 给排水采暖工程 | D27: ㎡ | E27: =经济技术指标!$D$10 | F27: =C27/E27*10000 | G27: 单体建筑面积 | H27: 专业工程指标
A28: 2.3.6 | B28: 楼宇亮化工程 | D28: ㎡ | E28: =经济技术指标!$D$10 | F28: =C28/E28*10000 | G28: 单体建筑面积 | H28: 专业工程指标
A29: 2.3.7 | B29: 电梯工程 | D29: ㎡ | E29: =经济技术指标!$D$10 | F29: =C29/E29*10000 | G29: 单体建筑面积 | H29: 专业工程指标
B30: ……
A31: 2.4 | B31: 2#楼工程 | C31: =SUM(C32:C38) | D31: ㎡ | E31: =经济技术指标!$D$11 | F31: =C31/E31*10000 | G31: 单体建筑面积 | H31: 单位工程指标
A32: 2.4.1 | B32: 电气设备安装工程 | D32: ㎡ | E32: =经济技术指标!$D$11 | F32: =C32/E32*10000 | G32: 单体建筑面积 | H32: 专业工程指标
A33: 2.4.2 | B33: 建筑智能化工程 | D33: ㎡ | E33: =经济技术指标!$D$11 | F33: =C33/E33*10000 | G33: 单体建筑面积 | H33: 专业工程指标
A34: 2.4.3 | B34: 通风空调工程 | D34: ㎡ | E34: =经济技术指标!$D$11 | F34: =C34/E34*10000 | G34: 单体建筑面积 | H34: 专业工程指标
A35: 2.4.4 | B35: 消防工程 | D35: ㎡ | E35: =经济技术指标!$D$11 | F35: =C35/E35*10000 | G35: 单体建筑面积 | H35: 专业工程指标
A36: 2.4.5 | B36: 给排水采暖工程 | D36: ㎡ | E36: =经济技术指标!$D$11 | F36: =C36/E36*10000 | G36: 地下建筑面积 | H36: 专业工程指标
A37: 2.4.6 | B37: 楼宇亮化工程 | D37: ㎡ | E37: =经济技术指标!$D$11 | F37: =C37/E37*10000 | G37: 单体建筑面积 | H37: 专业工程指标
A38: 2.4.7 | B38: 电梯工程 | D38: ㎡ | E38: =经济技术指标!$D$11 | F38: =C38/E38*10000 | G38: 单体建筑面积 | H38: 专业工程指标
B39: ……
A40: 2.5 | B40: 3#楼工程 | C40: =SUM(C41:C47) | D40: ㎡ | E40: =经济技术指标!$D$12 | F40: =C40/E40*10000 | G40: 单体建筑面积 | H40: 单位工程指标
...

Sheet 3.专项工程费
A1: 专项工程费分析表
A2: 项目名称：{{PROJECT_NAME}}
A3: 序号 | B3: 工程或费用名称 | C3: 费用（万元） | D3: 技术经济指标
D4: 单位 （x） | E4: 数量 | F4: 单方指标 （元/x） | G4: 计算基数 | H4: 指标说明
A5: 3 | B5: 专项工程费 | C5: =C6+C19+C29+C35+C42+C46+C47+C48+C49 | D5: ㎡ | E5: =经济技术指标!$D$5 | F5: =C5/E5*10000 | G5: 总建筑面积
A6: 3.1 | B6: 设备专项工程 | C6: =SUM(C7:C18) | D6: ㎡ | E6: =经济技术指标!$D$5 | F6: =C6/E6*10000 | G6: 总建筑面积 | H6: 专业工程指标
A7: 3.3.1 | B7: 柴油发电机组设备工程 | D7: KW | F7: =C7/E7*10000 | G7: 发电功率 | H7: 专业工程指标
A8: 3.3.2 | B8: 机械停车设备工程 | D8: 车位 | F8: =C8/E8*10000 | G8: 标准停车数量 | H8: 专业工程指标
A9: 3.3.3 | B9: 充电桩设备工程 | D9: 个 | F9: =C9/E9*10000 | G9: 设备数量 | H9: 专业工程指标
A10: 3.3.4 | B10: 太阳能光伏发电工程 | D10: kWp | F10: =C10/E10*10000 | G10: 峰值装机容量 | H10: 专业工程指标
A11: 3.3.5 | B11: 太阳能热水设备工程 | D11: ㎡ | F11: =C11/E11*10000 | G11: 总集热面积 | H11: 专业工程指标
A12: 3.3.6 | B12: 冷冻机房设备工程 | D12: kW | F12: =C12/E12*10000 | G12: 额定总制冷功率 | H12: 专业工程指标
A13: 3.3.7 | B13: 锅炉房设备工程 | D13: MW | F13: =C13/E13*10000 | G13: 额定供热功率 | H13: 专业工程指标
A14: 3.3.8 | B14: 洗衣机房设备工程 | D14: 套 | F14: =C14/E14*10000 | G14: 成套机组数量 | H14: 专业工程指标
A15: 3.3.9 | B15: 厨房设备工程 | D15: 套 | F15: =C15/E15*10000 | G15: 成套设备数量 | H15: 专业工程指标
A16: 3.3.10 | B16: 游泳池设备工程 | D16: m³ | F16: =C16/E16*10000 | G16: 设计水体总容积 | H16: 专业工程指标
A17: 3.3.11 | B17: 健身设备工程 | D17: 件 | F17: =C17/E17*10000 | G17: 健身设备数量 | H17: 专业工程指标
A18: 3.3.12 | B18: 污水处理站设备工程 | D18: m³/d | F18: =C18/E18*10000 | G18: 日处理污水规模 | H18: 专业工程指标
A19: 3.2 | B19: 医疗专项工程 | C19: =SUM(C20:C28) | D19: ㎡ | F19: =C19/E19*10000 | G19: 区域建筑面积 | H19: 专业工程指标
A20: 3.2.1 | B20: 洁净工程 | D20: ㎡ | F20: =C20/E20*10000 | G20: 洁净室建筑面积 | H20: 专业工程指标
A21: 3.2.2 | B21: 医用气体工程 | D21: 床位 | F21: =C21/E21*10000 | G21: 医院床位数 | H21: 专业工程指标
A22: 3.2.3 | B22: 医用纯水工程 | D22: m³/h | F22: =C22/E22*10000 | G22: 额定产水流量 | H22: 专业工程指标
A23: 3.2.4 | B23: 污水处理工程 | D23: m³/d | F23: =C23/E23*10000 | G23: 设计日处理规模 | H23: 专业工程指标
A24: 3.2.5 | B24: 放射防护工程 | D24: ㎡ | F24: =C24/E24*10000 | G24: 区域建筑面积 | H24: 专业工程指标
A25: 3.2.6 | B25: 病理科空气质量处理工程 | D25: ㎡ | F25: =C25/E25*10000 | G25: 区域建筑面积 | H25: 专业工程指标
A26: 3.2.7 | B26: 物流配送工程 | D26: 套 | F26: =C26/E26*10000 | G26: 传输成套系统 | H26: 专业工程指标
A27: 3.2.8 | B27: 床帘轨、输液轨安装工程 | D27: 套 | F27: =C27/E27*10000 | G27: 医院床位数 | H27: 专业工程指标
A28: 3.2.9 | B28: 医疗智能化工程 | D28: ㎡ | F28: =C28/E28*10000 | G28: 区域建筑面积 | H28: 专业工程指标
A29: 3.3 | B29: 教育专项工程 | C29: =SUM(C30:C34) | D29: ㎡ | F29: =C29/E29*10000 | G29: 区域建筑面积 | H29: 专业工程指标
A30: 3.3.1 | B30: 多媒体教学工程 | D30: 间 | F30: =C30/E30*10000 | G30: 多媒体教室数量 | H30: 专业工程指标
A31: 3.3.2 | B31: 录播系统工程 | D31: 间 | F31: =C31/E31*10000 | G31: 录播教室数量 | H31: 专业工程指标
A32: 3.3.3 | B32: 校园广播工程 | D32: ㎡ | F32: =C32/E32*10000 | G32: 校园建筑面积 | H32: 专业工程指标
A33: 3.3.4 | B33: 实验室工程 | D33: ㎡ | F33: =C33/E33*10000 | G33: 实验室建筑面积 | H33: 专业工程指标
A34: 3.3.5 | B34: 图书馆工程 | D34: ㎡ | F34: =C34/E34*10000 | G34: 图书馆建筑面积 | H34: 专业工程指标
A35: 3.4 | B35: 体育专项工程 | C35: =SUM(C36:C41) | D35: ㎡ | F35: =C35/E35*10000 | G35: 区域建筑面积 | H35: 专业工程指标
A36: 3.4.1 | B36: 足球场工程 | D36: 块 | F36: =C36/E36*10000 | G36: 标准球场数量 | H36: 专业工程指标
A37: 3.4.2 | B37: 排球馆工程 | D37: 片 | F37: =C37/E37*10000 | G37: 场地数量 | H37: 专业工程指标
A38: 3.4.3 | B38: 篮球馆工程 | D38: 片 | F38: =C38/E38*10000 | G38: 场地数量 | H38: 专业工程指标
A39: 3.4.4 | B39: 羽毛球馆工程 | D39: 片 | F39: =C39/E39*10000 | G39: 场地数量 | H39: 专业工程指标
A40: 3.4.5 | B40: 网球场工程 | D40: 片 | F40: =C40/E40*10000 | G40: 场地数量 | H40: 专业工程指标
...

Sheet 4.室外及配套工程费
A1: 室外及配套工程费专业分析表
A2: 项目名称：{{PROJECT_NAME}}
A3: 序号 | B3: 工程或费用名称 | C3: 费用（万元） | D3: 技术经济指标
D4: 单位 （x） | E4: 数量 | F4: 单方指标 （元/x） | G4: 计算基数 | H4: 指标说明
A5: 5 | B5: 室外及配套工程费 | C5: =C6+C10+C15+C21+C27+C28+C29+C30+C31 | D5: ㎡ | E5: =经济技术指标!$D$5 | F5: =C5/E5*10000 | G5: 总建筑面积 | H5: 单项工程指标
A6: 5.1 | B6: 室外园林工程 | C6: =SUM(C7:C8) | D6: ㎡ | E6: =经济技术指标!$D$17 | F6: =C6/E6*10000 | G6: 室外面积 | H6: 单位工程指标
A7: 5.1.1 | B7: 室外景观工程 | D7: ㎡ | F7: =C7/E7*10000 | G7: 室外景观面积 | H7: 专业工程指标
A8: 5.1.2 | B8: 室外绿化工程 | D8: ㎡ | F8: =C8/E8*10000 | G8: 绿地面积 | H8: 专业工程指标
B9: ……
A10: 5.2 | B10: 室外市政工程 | C10: =SUM(C11:C13) | D10: ㎡ | E10: =经济技术指标!$D$17 | F10: =C10/E10*10000 | G10: 室外面积 | H10: 单位工程指标
A11: 5.2.1 | B11: 室外市政道路工程 | D11: ㎡ | F11: =C11/E11*10000 | G11: 道路面积 | H11: 专业工程指标
A12: 5.2.2 | B12: 室外排水工程 | D12: ㎡ | E12: =经济技术指标!$D$17 | F12: =C12/E12*10000 | G12: 室外面积 | H12: 专业工程指标
A13: 5.2.3 | B13: 海棉城市工程 | D13: ㎡ | E13: =经济技术指标!$D$17 | F13: =C13/E13*10000 | G13: 室外面积 | H13: 专业工程指标
B14: ……
A15: 5.3 | B15: 室外附属工程 | C15: =SUM(C16:C19) | D15: ㎡ | E15: =经济技术指标!$D$17 | F15: =C15/E15*10000 | G15: 室外面积 | H15: 单位工程指标
A16: 5.3.1 | B16: 围墙 | D16: ㎡ | E16: =经济技术指标!$D$17 | F16: =C16/E16*10000 | G16: 室外面积 | H16: 专业工程指标
A17: 5.3.2 | B17: 挡土墙 | D17: ㎡ | E17: =经济技术指标!$D$17 | F17: =C17/E17*10000 | G17: 室外面积 | H17: 专业工程指标
A18: 5.3.3 | B18: 墙脚护坡、明沟、坡道、台阶 | D18: ㎡ | E18: =经济技术指标!$D$17 | F18: =C18/E18*10000 | G18: 室外面积 | H18: 专业工程指标
A19: 5.3.4 | B19: 化粪池 | D19: ㎡ | E19: =经济技术指标!$D$17 | F19: =C19/E19*10000 | G19: 室外面积 | H19: 专业工程指标
B20: ……
A21: 5.4 | B21: 室外安装工程 | C21: =SUM(C22:C25) | D21: ㎡ | E21: =经济技术指标!$D$17 | F21: =C21/E21*10000 | G21: 室外面积 | H21: 单位工程指标
A22: 5.4.1 | B22: 室外电气工程 | D22: ㎡ | E22: =经济技术指标!$D$17 | F22: =C22/E22*10000 | G22: 室外面积 | H22: 专业工程指标
A23: 5.4.2 | B23: 室外给水工程 | D23: ㎡ | E23: =经济技术指标!$D$17 | F23: =C23/E23*10000 | G23: 室外面积 | H23: 专业工程指标
A24: 5.4.3 | B24: 室外消防工程 | D24: ㎡ | E24: =经济技术指标!$D$17 | F24: =C24/E24*10000 | G24: 室外面积 | H24: 专业工程指标
A25: 5.4.4 | B25: 室外智能化工程 | D25: ㎡ | E25: =经济技术指标!$D$17 | F25: =C25/E25*10000 | G25: 室外面积 | H25: 专业工程指标
B26: ……
A27: 5.5 | B27: 变配电配套工程 | D27: ㎡ | E27: =经济技术指标!$D$5 | F27: =C27/E27*10000 | G27: 总建筑面积 | H27: 单位工程指标
A28: 5.6 | B28: 供水配套工程 | D28: ㎡ | E28: =经济技术指标!$D$5 | F28: =C28/E28*10000 | G28: 总建筑面积 | H28: 单位工程指标
A29: 5.7 | B29: 通讯配套工程 | D29: ㎡ | E29: =经济技术指标!$D$5 | F29: =C29/E29*10000 | G29: 总建筑面积 | H29: 单位工程指标
A30: 5.8 | B30: 燃气配套工程 | D30: ㎡ | E30: =经济技术指标!$D$5 | F30: =C30/E30*10000 | G30: 总建筑面积 | H30: 单位工程指标
A31: 5.9 | B31: 标识标牌配套工程 | D31: ㎡ | E31: =经济技术指标!$D$5 | F31: =C31/E31*10000 | G31: 总建筑面积 | H31: 单位工程指标
B32: ……

Sheet 5.工程建设其他费用
B1: 工程建设其他费分析表
A2: 项目名称：{{PROJECT_NAME}}
A3: 序号 | B3: 工程或费用名称 | C3: 费用 （万元） | D3: 技术经济指标 | I3: 费用计算 标准
D4: 单位 （x） | E4: 数量 | F4: 单方指标 （元/x） | G4: 计算基数 | H4: 指标 说明
A5: 二 | B5: 工程建设其他费用 | C5: =C6+C9+SUM(C14:C30) | D5: ㎡ | E5: =经济技术指标!$D$5 | F5: =C5/E5*10000 | G5: 总建筑面积
A6: 1 | B6: 项目建设管理费 | C6: =SUM(C7:C8) | D6: ㎡ | E6: =经济技术指标!$D$5 | F6: =C6/E6*10000 | G6: 总建筑面积 | I6: =_xlfn.DISPIMG("ID_62B8062AD4674B308CF07115098E9CA0",1)
A7: 1.1 | B7: 建设单位管理费 | D7: ㎡ | E7: =经济技术指标!$D$5 | F7: =C7/E7*10000 | G7: 总建筑面积
A8: 1.2 | B8: 项目管理费 | D8: ㎡ | E8: =经济技术指标!$D$5 | F8: =C8/E8*10000 | G8: 总建筑面积
A9: 2 | B9: 建设管理其他费 | C9: =SUM(C10:C13) | D9: ㎡ | E9: =经济技术指标!$D$5 | F9: =C9/E9*10000 | G9: 总建筑面积 | I9: =_xlfn.DISPIMG("ID_353356DCA9BF4818ADEE8EF7E4CAC740",1)
A10: 2.1 | B10: 建设项目前期咨询费 | D10: ㎡ | E10: =经济技术指标!$D$5 | F10: =C10/E10*10000 | G10: 总建筑面积
A11: 2.2 | B11: 工程招标代理费 | D11: ㎡ | E11: =经济技术指标!$D$5 | F11: =C11/E11*10000 | G11: 总建筑面积 | I11: =_xlfn.DISPIMG("ID_E011E42960CA49FC9CAA585277B222A4",1)
A12: 2.3 | B12: 工程造价咨询费 | D12: ㎡ | E12: =经济技术指标!$D$5 | F12: =C12/E12*10000 | G12: 总建筑面积 | I12: =_xlfn.DISPIMG("ID_BE8100AAD6C546B1BE1B6EDC5A9999CC",1)
A13: 2.4 | B13: 建设管理其他费 | D13: ㎡ | E13: =经济技术指标!$D$5 | F13: =C13/E13*10000 | G13: 总建筑面积
A14: 3 | B14: 工程监理费 | D14: ㎡ | E14: =经济技术指标!$D$5 | F14: =C14/E14*10000 | G14: 总建筑面积 | I14: =_xlfn.DISPIMG("ID_D84FC358A2F64DDE804D53059B1E6AE9",1)
A15: 4 | B15: 建设用地费 | D15: ㎡ | E15: =经济技术指标!$D$5 | F15: =C15/E15*10000 | G15: 总建筑面积
A16: 5 | B16: 可行性研究费 | D16: ㎡ | E16: =经济技术指标!$D$5 | F16: =C16/E16*10000 | G16: 总建筑面积 | I16: =_xlfn.DISPIMG("ID_F3F56E83FAF245A4904EEE4309A32062",1)
A17: 6 | B17: 勘察费设计费 | D17: ㎡ | E17: =经济技术指标!$D$5 | F17: =C17/E17*10000 | G17: 总建筑面积 | I17: =_xlfn.DISPIMG("ID_684596C7535E4F96BC0010F8FBD83BAE",1)
A18: 7 | B18: 环境影响评价费 | D18: ㎡ | E18: =经济技术指标!$D$5 | F18: =C18/E18*10000 | G18: 总建筑面积 | I18: =_xlfn.DISPIMG("ID_BE15CF6B8D374EFCBFA349ACF35114F0",1)
A19: 8 | B19: 节能评估费 | D19: ㎡ | E19: =经济技术指标!$D$5 | F19: =C19/E19*10000 | G19: 总建筑面积 | I19: =_xlfn.DISPIMG("ID_E6F3E89C98494E08A8F0FD3908047746",1)
A20: 9 | B20: 场地准备及临时设施费 | D20: ㎡ | E20: =经济技术指标!$D$5 | F20: =C20/E20*10000 | G20: 总建筑面积 | I20: =_xlfn.DISPIMG("ID_46EBB496AAB04C80B00328B58B21CD5E",1)
A21: 10 | B21: 工程保险费 | D21: ㎡ | E21: =经济技术指标!$D$5 | F21: =C21/E21*10000 | G21: 总建筑面积 | I21: =_xlfn.DISPIMG("ID_D0615DA30E6B4FDBB8896E561388EEA1",1)
A22: 11 | B22: 市政基础设施配套费 | D22: ㎡ | E22: =经济技术指标!$D$5 | F22: =C22/E22*10000 | G22: 总建筑面积 | I22: =_xlfn.DISPIMG("ID_BEBE3001711943D8AF784F6561D5932D",1)
A23: 12 | B23: 高可靠性供电费 | D23: ㎡ | E23: =经济技术指标!$D$5 | F23: =C23/E23*10000 | G23: 总建筑面积 | I23: =_xlfn.DISPIMG("ID_AEEA97D9156A4804AF567F76F3047D94",1)
A24: 13 | B24: 水土保持方案编制费 | D24: ㎡ | E24: =经济技术指标!$D$5 | F24: =C24/E24*10000 | G24: 总建筑面积
A25: 14 | B25: 工程检测费 | D25: ㎡ | E25: =经济技术指标!$D$5 | F25: =C25/E25*10000 | G25: 总建筑面积
A26: 15 | B26: BIM数字化服务费 | D26: ㎡ | E26: =经济技术指标!$D$5 | F26: =C26/E26*10000 | G26: 总建筑面积
A27: 16 | B27: 引进技术和引进设备其他费 | D27: ㎡ | E27: =经济技术指标!$D$5 | F27: =C27/E27*10000 | G27: 总建筑面积
A28: 17 | B28: 联合试运转费 | D28: ㎡ | E28: =经济技术指标!$D$5 | F28: =C28/E28*10000 | G28: 总建筑面积 | I28: =_xlfn.DISPIMG("ID_8EED7AD017BD4446994A41FDDD30B228",1)
A29: 18 | B29: 专利及专有技术使用费 | D29: ㎡ | E29: =经济技术指标!$D$5 | F29: =C29/E29*10000 | G29: 总建筑面积 | I29: =_xlfn.DISPIMG("ID_FA10EBB06CF14B70A36511F24BE2C0CE",1)
A30: 19 | B30: 生产准备及开办费 | D30: ㎡ | E30: =经济技术指标!$D$5 | F30: =C30/E30*10000 | G30: 总建筑面积 | I30: =_xlfn.DISPIMG("ID_947E9ED54A1C4897A716650557E3577C",1)
B31: ……

Sheet 1.1概算建筑项目清单
A1: 建筑工程概算项目清单
A2: 单位工程及专业工程名称： | J2: 建筑面积： | L2: 第 页共 页
A3: 序号 | B3: 项目 编码 | C3: 项目名称 | D3: 工作内容 | E3: 计量 单位 （x） | F3: 工程量 | G3: 单价 （元） | H3: 合价 （元） | I3: 经济指标 | K3: 工程量指标
I4: 单方指标 （元/㎡） | J4: 指标说明 | K4: 单方指标 （x/㎡） | L4: 计算基数
A5: 1 | C5: 土石方工程 | E5: m³ | J5: 单体建筑面积 | L5: 土石方开挖量
A6: 1.1 | C6: 场地平整 | E6: ㎡ | J6: 地下建筑面积 | L6: 首层建筑面积
A7: 1.2 | C7: 土石方开挖 | E7: m³ | J7: 单体建筑面积 | L7: 土石方开挖量
A8: 1.3 | C8: 土石方回填 | E8: m³ | J8: 单体建筑面积 | L8: 土石方回填量
A9: 1.4 | C9: 余方弃置 | E9: m³ | J9: 单体建筑面积 | L9: 弃置方量
A10: 2 | C10: 地基处理工程 | E10: m³ | J10: 单体建筑面积 | L10: 地基处理方量
A11: 2.1 | C11: 换填地基 | E11: m³ | J11: 单体建筑面积 | L11: 换填方量
A12: 2.2 | C12: 强夯地基 | E12: m³ | J12: 单体建筑面积 | L12: 强夯方量
A13: 2.3 | C13: 预压地基 | E13: m³ | J13: 单体建筑面积 | L13: 预压方量
A14: 2.4 | C14: 复合地基 | E14: m³ | J14: 单体建筑面积 | L14: 复合方量
A15: 2.5 | C15: 加固地基 | E15: m³ | J15: 单体建筑面积 | L15: 加固方量
A16: 3 | C16: 基坑与边坡支护工程 | E16: m | J16: 地下建筑面积 | L16: 支护长度
... A91: 16.4 | C91: 其他天棚 | E91: ㎡ | J91: 单体建筑面积 | L91: 其他天棚面积
A92: 17 | C92: 其他装饰工程 | E92: 项 | J92: 单体建筑面积
A93: 17.1 | C93: 扶手、栏杆、栏板装饰 | E93: m | J93: 单体建筑面积 | L93: 扶手栏杆长度
A94: 17.2 | C94: 柜类、货架及柜台 | E94: ㎡ | J94: 单体建筑面积 | L94: 柜类面积
A95: 17.3 | C95: 装饰线条 | E95: m | J95: 单体建筑面积 | L95: 线条长度
A96: 17.4 | C96: 浴厕集成 | E96: ㎡ | J96: 单体建筑面积 | L96: 浴厕集成面积
A97: 17.5 | C97: 其他装饰 | E97: ㎡ | J97: 单体建筑面积 | L97: 其他装饰面积
A98: 18 | C98: 构筑物工程 | E98: m³ | J98: 单体建筑面积 | L98: 构筑物体积
A99: 18.1 | C99: 烟囱 | E99: m³ | J99: 单体建筑面积 | L99: 构筑物体积
A100: 18.2 | C100: 水塔 | E100: m³ | J100: 单体建筑面积 | L100: 构筑物体积
A101: 18.3 | C101: 钢筋混凝土贮水(油)池 | E101: m³ | J101: 单体建筑面积 | L101: 构筑物体积
A102: 18.4 | C102: 贮仓 | E102: m³ | J102: 单体建筑面积 | L102: 构筑物体积
A103: 19 | C103: 附属工程 | E103: 项 | J103: 单体建筑面积
A104: 19.1 | C104: 围墙 | E104: m | J104: 单体建筑面积 | L104: 围墙长度
A105: 19.2 | C105: 操场、球场
A106: 19.3 | C106: 挡土墙 | E106: m | J106: 单体建筑面积 | L106: 挡土墙长度
A107: 19.4 | C107: 墙脚护坡、明沟、坡道、台阶 | E107: ㎡ | J107: 单体建筑面积 | L107: 护坡台阶面积
A108: 19.5 | C108: 排水管道铺设 | E108: m | J108: 单体建筑面积 | L108: 管道长度
A109: 19.6 | C109: 窨井、检查井 | E109: 套 | J109: 单体建筑面积 | L109: 井数量
A110: 19.7 | C110: 化粪池 | E110: m³ | J110: 单体建筑面积 | L110: 化粪池方量
A111: 19.8 | C111: 其他附属 | E111: 项 | J111: 单体建筑面积
A112: 20 | C112: 拆除工程 | E112: ㎡ | J112: 单体建筑面积 | L112: 拆除总面积
A113: 20.1 | C113: 结构拆除 | E113: m³ | J113: 单体建筑面积 | L113: 结构拆除体积
A114: 20.2 | C114: 饰面拆除 | E114: ㎡ | J114: 单体建筑面积 | L114: 饰面拆除面积
...

Sheet 2.1估概算安装项目清单
A1: 安装工程概算项目清单
A2: 单位工程及专业工程名称： | J2: 建筑面积： | L2: 第 页共 页
A3: 序号 | B3: 项目 编码 | C3: 项目名称 | D3: 工作内容 | E3: 计量 单位 （x） | F3: 工程量 | G3: 单价 （元） | H3: 合价 （元） | I3: 经济指标 | K3: 工程量指标
I4: 单方指标 （元/㎡） | J4: 指标说明 | K4: 单方指标 （x/㎡） | L4: 计算基数
A5: 1 | C5: 电气工程 | E5: ㎡ | J5: 单体建筑面积
A6: 1.1 | C6: 配电箱（含充电桩） | E6: 套 | J6: 单体建筑面积 | L6: 配电箱套数
A7: 1.2 | C7: 桥架敷设（含支架） | E7: m | J7: 单体建筑面积 | L7: 桥架长度
A8: 1.3 | C8: 配管工程（含接线盒） | E8: m | J8: 单体建筑面积 | L8: 配管长度
A9: 1.4 | C9: 配线工程 | E9: m | J9: 单体建筑面积 | L9: 配线长度
A10: 1.5 | C10: 电缆敷设 | E10: m | J10: 单体建筑面积 | L10: 电缆长度
A11: 1.6 | C11: 母线安装（含插接箱、始端箱） | E11: m | J11: 单体建筑面积 | L11: 母线长度
A12: 1.7 | C12: 照明灯具、开关插座 | E12: 套 | J12: 单体建筑面积 | L12: 灯具套数
A13: 1.8 | C13: 防雷接地系统 | E13: m | J13: 单体建筑面积 | L13: 防雷接地长度
A14: 1.9 | C14: 人防电气系统 | E14: ㎡ | J14: 单体建筑面积 | L14: 人防面积
A15: 1.1 | C15: 其他电气设备安装（调试、套管等） | E15: ㎡ | J15: 单体建筑面积 | L15: 单体建筑面积
A16: 2 | C16: 给排水工程 | E16: ㎡ | J16: 单体建筑面积
A17: 2.1 | C17: 给水系统（含支架、套管，余同） | E17: m | J17: 地下建筑面积 | L17: 给水长度
A18: 2.2 | C18: 热水系统 | E18: m | J18: 地下建筑面积 | L18: 热水长度
A19: 2.3 | C19: 污废水系统 | E19: m | J19: 地下建筑面积 | L19: 污废水长度
A20: 2.4 | C20: 压力排水系统 | E20: m | J20: 单体建筑面积 | L20: 压力排水长度
A21: 2.5 | C21: 雨水系统 | E21: m | J21: 单体建筑面积 | L21: 雨水长度
A22: 2.6 | C22: 卫生器具安装 | E22: 套 | J22: 单体建筑面积 | L22: 卫生器具套数
A23: 2.7 | C23: 人防给排水系统 | E23: m | J23: 单体建筑面积 | L23: 人防给排水长度
A24: 2.8 | C24: 再生水、中水系统 | E24: m | J24: 单体建筑面积 | L24: 再生水、中水长度
A25: 2.9 | C25: 雨水回收系统 | E25: m | J25: 单体建筑面积 | L25: 雨水回收长度
A26: 2.1 | C26: 其他给排水系统 | E26: m | J26: 单体建筑面积 | L26: 其他给排水长度
A27: 3 | C27: 消防工程 | E27: ㎡ | J27: 单体建筑面积
A28: 3.1 | C28: 水灭火系统-自动喷淋灭火系统 | E28: m | J28: 单体建筑面积 | L28: 自动喷淋长度
A29: 3.2 | C29: 水灭火系统-消火栓系统 | E29: 套 | J29: 单体建筑面积 | L29: 消火栓套数
A30: 3.3 | C30: 水灭火系统-消防水炮系统 | E30: 套 | J30: 单体建筑面积 | L30: 消防水炮套数
A31: 3.4 | C31: 气体灭火系统 | E31: 套 | J31: 单体建筑面积 | L31: 气体灭火套数
A32: 3.5 | C32: 泡沫灭火系统 | E32: 套 | J32: 单体建筑面积 | L32: 泡沫灭火套数
A33: 3.6 | C33: 火灾自动报警系统 | E33: 套 | J33: 单体建筑面积 | L33: 火灾自动报警套数
A34: 3.7 | C34: 电气火灾监控系统 | E34: 套 | J34: 单体建筑面积 | L34: 电气火灾监控套数
A35: 3.8 | C35: 消防电源监控系统 | E35: 套 | J35: 单体建筑面积 | L35: 消防电源监控套数
A36: 3.9 | C36: 防火门监控系统 | E36: 套 | J36: 单体建筑面积 | L36: 防火门监控套数
A37: 3.1 | C37: 余压监控系统 | E37: 套 | J37: 单体建筑面积 | L37: 余压监控套数
A38: 3.11 | C38: 应急照明及疏散指示系统 | E38: 套 | J38: 单体建筑面积 | L38: 应急照明及疏散指示套数
A39: 3.12 | C39: 其他消防系统 | E39: 套 | J39: 单体建筑面积 | L39: 其他消防套数
A40: 4 | C40: 通风空调、采暖工程 | E40: ㎡ | J40: 单体建筑面积
...
